import React from 'react';
import { render, screen, fireEvent } from '@testing-library/react';
import { vi } from 'vitest';
import { ErrorBoundary } from '../ErrorBoundary';

// Mock component that throws an error
const ThrowError = ({ shouldThrow }: { shouldThrow: boolean }) => {
  if (shouldThrow) {
    throw new Error('Test error');
  }
  return <div>No error</div>;
};

describe('ErrorBoundary', () => {
  const originalEnv = process.env.NODE_ENV;
  
  beforeEach(() => {
    vi.clearAllMocks();
    // Suppress console.error for tests
    vi.spyOn(console, 'error').mockImplementation(() => {});
  });

  afterEach(() => {
    process.env.NODE_ENV = originalEnv;
    vi.restoreAllMocks();
  });

  it('renders children when there is no error', () => {
    render(
      <ErrorBoundary>
        <ThrowError shouldThrow={false} />
      </ErrorBoundary>
    );

    expect(screen.getByText('No error')).toBeInTheDocument();
  });

  it('renders error UI when there is an error', () => {
    render(
      <ErrorBoundary>
        <ThrowError shouldThrow={true} />
      </ErrorBoundary>
    );

    expect(screen.getByText('Something went wrong')).toBeInTheDocument();
    expect(screen.getByText(/We encountered an unexpected error/)).toBeInTheDocument();
    expect(screen.getByText('Try Again')).toBeInTheDocument();
    expect(screen.getByText('Refresh Page')).toBeInTheDocument();
  });

  it('shows error details in development mode', () => {
    process.env.NODE_ENV = 'development';
    
    render(
      <ErrorBoundary>
        <ThrowError shouldThrow={true} />
      </ErrorBoundary>
    );

    expect(screen.getByText('Error Details (Development)')).toBeInTheDocument();
  });

  it('hides error details in production mode', () => {
    process.env.NODE_ENV = 'production';
    
    render(
      <ErrorBoundary>
        <ThrowError shouldThrow={true} />
      </ErrorBoundary>
    );

    expect(screen.queryByText('Error Details (Development)')).not.toBeInTheDocument();
  });

  it('calls onError callback when error occurs', () => {
    const onError = vi.fn();
    
    render(
      <ErrorBoundary onError={onError}>
        <ThrowError shouldThrow={true} />
      </ErrorBoundary>
    );

    expect(onError).toHaveBeenCalledWith(
      expect.any(Error),
      expect.objectContaining({
        componentStack: expect.any(String)
      })
    );
  });

  it('renders custom fallback when provided', () => {
    const customFallback = <div>Custom error message</div>;
    
    render(
      <ErrorBoundary fallback={customFallback}>
        <ThrowError shouldThrow={true} />
      </ErrorBoundary>
    );

    expect(screen.getByText('Custom error message')).toBeInTheDocument();
    expect(screen.queryByText('Something went wrong')).not.toBeInTheDocument();
  });

  it('has retry functionality', () => {
    render(
      <ErrorBoundary>
        <ThrowError shouldThrow={true} />
      </ErrorBoundary>
    );

    expect(screen.getByText('Something went wrong')).toBeInTheDocument();
    
    const retryButton = screen.getByText('Try Again');
    expect(retryButton).toBeInTheDocument();
    
    // Verify the button is clickable (doesn't throw)
    expect(() => fireEvent.click(retryButton)).not.toThrow();
  });

  it('refreshes page when Refresh Page is clicked', () => {
    const mockReload = vi.fn();
    Object.defineProperty(window, 'location', {
      value: { reload: mockReload },
      writable: true
    });

    render(
      <ErrorBoundary>
        <ThrowError shouldThrow={true} />
      </ErrorBoundary>
    );

    fireEvent.click(screen.getByText('Refresh Page'));

    expect(mockReload).toHaveBeenCalled();
  });
});